# tool_scripts
## ubuntu问题
ubuntu一些版本的openssl升级到1.1.0以上，导致shadowsocks启动错误

```log
INFO: loading config from /etc/shadowsocks.json
2019-10-12 19:42:45 INFO     loading libcrypto from libcrypto.so.1.1
Traceback (most recent call last):
  File "/usr/local/bin/ssserver", line 11, in <module>
    load_entry_point('shadowsocks==2.8.2', 'console_scripts', 'ssserver')()
  File "/usr/local/lib/python2.7/dist-packages/shadowsocks/server.py", line 34, in main
    config = shell.get_config(False)
  File "/usr/local/lib/python2.7/dist-packages/shadowsocks/shell.py", line 262, in get_config
    check_config(config, is_local)
  File "/usr/local/lib/python2.7/dist-packages/shadowsocks/shell.py", line 124, in check_config
    encrypt.try_cipher(config['password'], config['method'])
  File "/usr/local/lib/python2.7/dist-packages/shadowsocks/encrypt.py", line 44, in try_cipher
    Encryptor(key, method)
  File "/usr/local/lib/python2.7/dist-packages/shadowsocks/encrypt.py", line 83, in __init__
    random_string(self._method_info[1]))
  File "/usr/local/lib/python2.7/dist-packages/shadowsocks/encrypt.py", line 109, in get_cipher
    return m[2](method, key, iv, op)
  File "/usr/local/lib/python2.7/dist-packages/shadowsocks/crypto/openssl.py", line 76, in __init__
    load_openssl()
  File "/usr/local/lib/python2.7/dist-packages/shadowsocks/crypto/openssl.py", line 52, in load_openssl
    libcrypto.EVP_CIPHER_CTX_cleanup.argtypes = (c_void_p,)
  File "/usr/lib/python2.7/ctypes/__init__.py", line 379, in __getattr__
    func = self.__getitem__(name)
  File "/usr/lib/python2.7/ctypes/__init__.py", line 384, in __getitem__
    func = self._FuncPtr((name_or_ordinal, self))
AttributeError: /usr/lib/x86_64-linux-gnu/libcrypto.so.1.1: undefined symbol: EVP_CIPHER_CTX_cleanup
```

解决办法是将`/usr/local/lib/python2.7/dist-packages/shadowsocks/crypto/openssl.py`中的`EVP_CIPHER_CTX_cleanup`更改为`EVP_CIPHER_CTX_reset`

## pip error

```log
Traceback (most recent call last):
  File "/usr/bin/pip3", line 11, in <module>
    sys.exit(main())
  File "/usr/lib/python3/dist-packages/pip/__init__.py", line 215, in main
    locale.setlocale(locale.LC_ALL, '')
  File "/usr/lib/python3.5/locale.py", line 594, in setlocale
    return _setlocale(category, locale)
locale.Error: unsupported locale setting
```

显示`LC_ALL`出错，解决方法:

```shell
export LC_ALL=C
```

